<mujoco model="humanoid">
    <compiler angle="degree" inertiafromgeom="true"/>
    <default>
        <joint armature="1" damping="1" limited="true"/>
        <geom conaffinity="1" condim="3" friction="0.8 0.1 0.1" contype="1" margin="0.001" material="geom" rgba="0.8 0.6 .4 1"/>
        <motor ctrllimited="true" ctrlrange="-.4 .4"/>
    </default>
    <option integrator="RK4" iterations="50" solver="PGS" timestep="0.003">
        <!-- <flags solverstat="enable" energy="enable"/>-->
    </option>
    <size nkey="5" nuser_geom="1"/>
    <visual>
        <map fogend="5" fogstart="3"/>
    </visual>
    <worldbody>
        <body name="torso" pos="0 0 1.4">
            <!--joint axis="0 0 0" armature="0" damping="0" limited="false" name="root" pos="0 0 0" stiffness="0" type="fixed"/-->
            <body name="ribs" pos="0 0 0">
                <joint axis="0 0 1" name="ribs_fix" pos="0 0 0" range="0 0" type="fixed"/>
                <geom fromto="0 -.07 0 0 .07 0" name="torso1" size="0.07" type="capsule"/>
            </body>
            <geom fromto="-.01 -.06 -.12 -.01 .06 -.12" name="uwaist" size="0.06" type="capsule"/>
            <body name="head" pos="0 0 .19">
                <joint axis="0 0 1" name="head_fix" pos="0 0 0" range="0 0" type="fixed"/>
                <geom name="head" pos="0 0 0" size=".09" type="sphere" user="258"/>
            </body>
            <body name="lwaist" pos="-.01 0 -0.260" quat="1.000 0 -0.002 0">
                <geom fromto="0 -.06 0 0 .06 0" name="lwaist" size="0.06" type="capsule"/>
                <joint armature="0.02" axis="0 0 1" damping="5" name="abdomen_z" pos="0 0 0.065" range="-45 45" stiffness="20" type="hinge"/>
                <joint armature="0.02" axis="0 1 0" damping="5" name="abdomen_y" pos="0 0 0.065" range="-75 30" stiffness="10" type="hinge"/>
                <body name="pelvis" pos="0 0 -0.165" quat="1.000 0 -0.002 0">
                    <joint armature="0.02" axis="1 0 0" damping="5" name="abdomen_x" pos="0 0 0.1" range="-35 35" stiffness="10" type="hinge"/>
                    <geom fromto="-.02 -.07 0 -.02 .07 0" name="butt" size="0.09" type="capsule"/>
                    <body name="right_thigh" pos="0 -0.1 -0.04">
                        <joint armature="0.01" axis="1 0 0" damping="5" name="right_hip_x" pos="0 0 0" range="-25 5" stiffness="10" type="hinge"/>
                        <joint armature="0.01" axis="0 0 1" damping="5" name="right_hip_z" pos="0 0 0" range="-60 35" stiffness="10" type="hinge"/>
                        <joint armature="0.01" axis="0 1 0" damping="5" name="right_hip_y" pos="0 0 0" range="-120 20" stiffness="20" type="hinge"/>
                        <geom fromto="0 0 0 0 0.01 -.34" name="right_thigh1" size="0.06" type="capsule"/>
                        <body name="right_shin" pos="0 0.01 -0.403">
                            <joint armature="0.0060" axis="0 -1 0" name="right_knee" pos="0 0 .02" range="-160 -2" stiffness="1" type="hinge"/>
                            <geom fromto="0 0 0 0 0 -.3" name="right_shin1" size="0.049" type="capsule"/>
                            <body name="right_foot" pos="0 0 -0.45">
                                <geom name="right_foot" pos="0 0 0.1" size="0.075" type="sphere" user="0"/>
                            </body>
                        </body>
                    </body>
                    <body name="left_thigh" pos="0 0.1 -0.04">
                        <joint armature="0.01" axis="-1 0 0" damping="5" name="left_hip_x" pos="0 0 0" range="-25 5" stiffness="10" type="hinge"/>
                        <joint armature="0.01" axis="0 0 -1" damping="5" name="left_hip_z" pos="0 0 0" range="-60 35" stiffness="10" type="hinge"/>
                        <joint armature="0.01" axis="0 1 0" damping="5" name="left_hip_y" pos="0 0 0" range="-120 20" stiffness="20" type="hinge"/>
                        <geom fromto="0 0 0 0 -0.01 -.34" name="left_thigh1" size="0.06" type="capsule"/>
                        <body name="left_shin" pos="0 -0.01 -0.403">
                            <joint armature="0.0060" axis="0 -1 0" name="left_knee" pos="0 0 .02" range="-160 -2" stiffness="1" type="hinge"/>
                            <geom fromto="0 0 0 0 0 -.3" name="left_shin1" size="0.049" type="capsule"/>
                            <body name="left_foot" pos="0 0 -0.45">
                                <geom name="left_foot" type="sphere" size="0.075" pos="0 0 0.1" user="0" />
                            </body>
                        </body>
                    </body>
                </body>
            </body>
            <body name="right_upper_arm" pos="0 -0.17 0.06">
                <joint axis="0 0 1" name="right_shoulder_pan" pos="0 0 0" range="-25 90" stiffness="1" type="hinge"/>
                <joint axis="-1 0 0" name="right_shoulder_lift" pos="0 0 0" range="-90 90" stiffness="1" type="hinge"/>
                <geom fromto="0 0 0  0 -.25 0" name="right_uarm1" size="0.04" type="capsule"/>
                <body name="right_lower_arm" pos="0 -.28 0">
                    <joint axis="0 1 0" name="right_elbow_tilt" pos="0 0 0" range="-25 180" stiffness="0" type="hinge"/>
                    <joint axis="-1 0 0" name="right_elbow_bend" pos="0 0 0" range="0 150" stiffness="0" type="hinge"/>
                    <geom fromto="0 0 0  0 -0.27 0" name="right_larm" size="0.031" type="capsule"/>
                    <geom name="right_hand" pos="0 -.27 0" size="0.04" type="sphere"/>
                    <body name="racquet_handle" pos="0 -.27 0">
                        <joint axis="1 0 0" name="racquet_rock" pos="0 0 0" range="-40 80" stiffness="0" type="hinge"/>
                        <geom fromto="0 0 0.02  0 0 .22" rgba="1 1 1 1" name="racquet_handle" size="0.01" type="cylinder"/>
                        <inertial mass="0.1"/>
                        <body name="racquet_head" pos="0 0 .35">
                            <joint axis="1 1 1" name="racquet_head_fix" pos="0 0 0" range="-120 120" stiffness="0" type="fixed"/>
                            <geom fromto="-.005 0 0  +0.005 0 0" rgba="1 1 1 1" name="racquet_head" size="0.12" type="cylinder"/>
                            <inertial mass="0.1"/>
                        </body>
                    </body>
                </body>
            </body>
            <body name="left_upper_arm" pos="0 0.17 0.06">
                <joint axis="0 0 -1"  name="left_shoulder_pan" pos="0 0 0" range="-25 90" stiffness="1" type="hinge"/>
                <joint axis="1 0 0" name="left_shoulder_lift" pos="0 0 0" range="-90 90" stiffness="1" type="hinge"/>
                <geom fromto="0 0 0  0 +0.25 0" name="left_uarm1" size="0.04" type="capsule"/>
                <body name="left_lower_arm" pos="0 0.28 0">
                    <joint axis="0 1 0" name="left_elbow_tilt" pos="0 0 0" range="-25 180" stiffness="0" type="hinge"/>
                    <joint axis="1 0 0" name="left_elbow_bend" pos="0 0 0" range="0 150" stiffness="0" type="hinge"/>
                    <geom fromto="0 0 0  0 +0.27 0" name="left_larm" size="0.031" type="capsule"/>
                    <geom name="left_hand" pos="0 .27 0" size="0.04" type="sphere"/>
                </body>
            </body>
        </body>
    </worldbody>
</mujoco>
